<sdf version='1.6'>
  <model name='pi_robot'>
    <link name='base_link'>
      <pose frame=''>0 0 0 0 -0 0</pose>
      <inertial>
        <pose frame=''>0.009583 0 0.053646 0 -0 0</pose>
        <mass>12</mass>
        <inertia>
          <ixx>4.01509</ixx>
          <ixy>0</ixy>
          <ixz>-0.00419323</ixz>
          <iyy>4.03082</iyy>
          <iyz>0</iyz>
          <izz>4.01572</izz>
        </inertia>
      </inertial>
      <collision name='base_link_collision'>
        <pose frame=''>0 0 0.0425 0 -0 0</pose>
        <geometry>
          <box>
            <size>0.32 0.26 0.085</size>
          </box>
        </geometry>
      </collision>
      <collision name='base_link_fixed_joint_lump__base_laser_collision_1'>
        <pose frame=''>0.18 0 0.07 0 -0 0</pose>
        <geometry>
          <cylinder>
            <length>0.07</length>
            <radius>0.025</radius>
          </cylinder>
        </geometry>
      </collision>
      <collision name='base_link_fixed_joint_lump__cpu_link_collision_2'>
        <pose frame=''>0.025 0 0.12 0 -0 0</pose>
        <geometry>
          <box>
            <size>0.19 0.19 0.07</size>
          </box>
        </geometry>
      </collision>
      <collision name='base_link_fixed_joint_lump__upper_base_link_collision_3'>
        <pose frame=''>0.025 0 0.205 0 -0 0</pose>
        <geometry>
          <cylinder>
            <length>0.1</length>
            <radius>0.085</radius>
          </cylinder>
        </geometry>
      </collision>
      <visual name='base_link_visual'>
        <pose frame=''>0 0 0.0425 0 -0 0</pose>
        <geometry>
          <box>
            <size>0.32 0.26 0.085</size>
          </box>
        </geometry>
        <material>
            <script>
            <uri>file://media/materials/scripts/gazebo.material</uri>
            <name>Gazebo/Blue</name>
            </script>
        </material>
      </visual>
      <visual name='base_link_fixed_joint_lump__base_laser_visual_1'>
        <pose frame=''>0.18 0 0.07 0 -0 0</pose>
        <geometry>
          <cylinder>
            <length>0.07</length>
            <radius>0.025</radius>
          </cylinder>
        </geometry>
        <material>
            <script>
            <uri>file://media/materials/scripts/gazebo.material</uri>
            <name>Gazebo/Black</name>
            </script>
        </material>
      </visual>
      <visual name='base_link_fixed_joint_lump__cpu_link_visual_2'>
        <pose frame=''>0.025 0 0.12 0 -0 0</pose>
        <geometry>
          <box>
            <size>0.19 0.19 0.07</size>
          </box>
        </geometry>
        <material>
            <script>
            <uri>file://media/materials/scripts/gazebo.material</uri>
            <name>Gazebo/Blue</name>
            </script>
        </material>
      </visual>
      <visual name='base_link_fixed_joint_lump__upper_base_link_visual_3'>
        <pose frame=''>0.025 0 0.205 0 -0 0</pose>
        <geometry>
          <cylinder>
            <length>0.1</length>
            <radius>0.085</radius>
          </cylinder>
        </geometry>
        <material>
            <script>
            <uri>file://media/materials/scripts/gazebo.material</uri>
            <name>Gazebo/SkyBlue</name>
            </script>
        </material>
      </visual>
    </link>
    
    <link name='torso_link'>
      <pose frame=''>0.025 0 0.255 0 -0 0</pose>
      <inertial>
        <pose frame=''>0 0 0.174375 0 -0 0</pose>
        <mass>2</mass>
        <inertia>
          <ixx>4.00726</ixx>
          <ixy>0</ixy>
          <ixz>0</ixz>
          <iyy>4.00424</iyy>
          <iyz>0</iyz>
          <izz>4.00303</izz>
        </inertia>
      </inertial>
      <collision name='torso_link_collision'>
        <pose frame=''>0 0 0.12 0 -0 0</pose>
        <geometry>
          <cylinder>
            <length>0.24</length>
            <radius>0.05</radius>
          </cylinder>
        </geometry>
      </collision>
      <collision name='torso_link_fixed_joint_lump__head_pan_link_collision_1'>
        <pose frame=''>0 0 0.2475 0 -0 0</pose>
        <geometry>
          <box>
            <size>0.05 0.045 0.045</size>
          </box>
        </geometry>
      </collision>
      <collision name='torso_link_fixed_joint_lump__left_shoulder_link_collision_2'>
        <pose frame=''>0 0.055 0.165 0 -0 0</pose>
        <geometry>
          <box>
            <size>0.025 0.015 0.05</size>
          </box>
        </geometry>
      </collision>
      <collision name='torso_link_fixed_joint_lump__right_shoulder_link_collision_3'>
        <pose frame=''>0 -0.055 0.165 0 -0 0</pose>
        <geometry>
          <box>
            <size>0.025 0.015 0.05</size>
          </box>
        </geometry>
      </collision>
      <visual name='torso_link_visual'>
        <pose frame=''>0 0 0.12 0 -0 0</pose>
        <geometry>
          <cylinder>
            <length>0.24</length>
            <radius>0.05</radius>
          </cylinder>
        </geometry>
        <material>
            <script>
            <uri>file://media/materials/scripts/gazebo.material</uri>
            <name>Gazebo/Yellow</name>
            </script>
        </material>
      </visual>
      <visual name='torso_link_fixed_joint_lump__head_pan_link_visual_1'>
        <pose frame=''>0 0 0.2475 0 -0 0</pose>
        <geometry>
          <box>
            <size>0.05 0.045 0.045</size>
          </box>
        </geometry>
        <material>
            <script>
            <uri>file://media/materials/scripts/gazebo.material</uri>
            <name>Gazebo/Green</name>
            </script>
        </material>
      </visual>
      <visual name='torso_link_fixed_joint_lump__left_shoulder_link_visual_2'>
        <pose frame=''>0 0.055 0.165 0 -0 0</pose>
        <geometry>
          <box>
            <size>0.025 0.015 0.05</size>
          </box>
        </geometry>
        <material>
            <script>
            <uri>file://media/materials/scripts/gazebo.material</uri>
            <name>Gazebo/Green</name>
            </script>
        </material>
      </visual>
      <visual name='torso_link_fixed_joint_lump__right_shoulder_link_visual_3'>
        <pose frame=''>0 -0.055 0.165 0 -0 0</pose>
        <geometry>
          <box>
            <size>0.025 0.015 0.05</size>
          </box>
        </geometry>
        <material>
            <script>
            <uri>file://media/materials/scripts/gazebo.material</uri>
            <name>Gazebo/Green</name>
            </script>
        </material>
      </visual>
    </link>
    
    <joint name='torso_joint' type='revolute'>
      <child>torso_link</child>
      <parent>base_link</parent>
      <axis>
        <xyz>0 0 1</xyz>
        <limit>
          <lower>-3.1416</lower>
          <upper>3.1416</upper>
          <effort>10</effort>
          <velocity>3</velocity>
        </limit>
        <dynamics>
          <spring_reference>0</spring_reference>
          <spring_stiffness>0</spring_stiffness>
        </dynamics>
        <use_parent_model_frame>1</use_parent_model_frame>
      </axis>
    </joint>
    
    <link name='head_tilt_link'>
      <pose frame=''>0.025 0 0.525 0 -0 0</pose>
      <inertial>
        <pose frame=''>0 0 0.02 0 -0 0</pose>
        <mass>0.5</mass>
        <inertia>
          <ixx>1</ixx>
          <ixy>0</ixy>
          <ixz>0</ixz>
          <iyy>1</iyy>
          <iyz>0</iyz>
          <izz>1</izz>
        </inertia>
      </inertial>
      <collision name='head_tilt_link_collision'>
        <pose frame=''>0 0 0.02 0 -0 0</pose>
        <geometry>
          <box>
            <size>0.03 0.038 0.04</size>
          </box>
        </geometry>
      </collision>
      <visual name='head_tilt_link_visual'>
        <pose frame=''>0 0 0.02 0 -0 0</pose>
        <geometry>
          <box>
            <size>0.03 0.038 0.04</size>
          </box>
        </geometry>
        <material>
            <script>
            <uri>file://media/materials/scripts/gazebo.material</uri>
            <name>Gazebo/Green</name>
            </script>
        </material>
      </visual>
    </link>
    
    <joint name='head_pan_joint' type='revolute'>
      <child>head_tilt_link</child>
      <parent>torso_link</parent>
      <axis>
        <xyz>0 0 1</xyz>
        <limit>
          <lower>-3.1416</lower>
          <upper>3.1416</upper>
          <effort>10</effort>
          <velocity>3</velocity>
        </limit>
        <dynamics>
          <spring_reference>0</spring_reference>
          <spring_stiffness>0</spring_stiffness>
        </dynamics>
        <use_parent_model_frame>1</use_parent_model_frame>
      </axis>
    </joint>
    
    
    <link name='neck_link'>
      <pose frame=''>0.025 0 0.565 0 -0 0</pose>
      <inertial>
        <pose frame=''>0.033333 -0.008333 0.058667 0 -0 0</pose>
        <mass>1.5</mass>
        <inertia>
          <ixx>3.00268</ixx>
          <ixy>0.000208333</ixy>
          <ixz>-0.000941667</ixz>
          <iyy>3.0033</iyy>
          <iyz>0.000704167</iyz>
          <izz>3.00104</izz>
        </inertia>
      </inertial>
      <collision name='neck_link_collision'>
        <pose frame=''>0 0 0.021 0 -0 0</pose>
        <geometry>
          <box>
            <size>0.03 0.05 0.042</size>
          </box>
        </geometry>
      </collision>
      <collision name='neck_link_fixed_joint_lump__head_link_collision_1'>
        <pose frame=''>0.05 0 0.04 0 -0 0</pose>
        <geometry>
          <box>
            <size>0.03 0.07 0.11</size>
          </box>
        </geometry>
      </collision>
      <collision name='neck_link_fixed_joint_lump__antenna_link_collision_2'>
        <pose frame=''>0.05 -0.025 0.115 0 -0 0</pose>
        <geometry>
          <cylinder>
            <length>0.05</length>
            <radius>0.002</radius>
          </cylinder>
        </geometry>
      </collision>
      <visual name='neck_link_visual'>
        <pose frame=''>0 0 0.021 0 -0 0</pose>
        <geometry>
          <box>
            <size>0.03 0.05 0.042</size>
          </box>
        </geometry>
        <material>
            <script>
            <uri>file://media/materials/scripts/gazebo.material</uri>
            <name>Gazebo/Green</name>
            </script>
        </material>
      </visual>
      <visual name='neck_link_fixed_joint_lump__head_link_visual_1'>
        <pose frame=''>0.05 0 0.04 0 -0 0</pose>
        <geometry>
          <box>
            <size>0.03 0.07 0.11</size>
          </box>
        </geometry>
        <material>
            <script>
            <uri>file://media/materials/scripts/gazebo.material</uri>
            <name>Gazebo/Grey</name>
            </script>
        </material>
      </visual>
      <visual name='neck_link_fixed_joint_lump__antenna_link_visual_2'>
        <pose frame=''>0.05 -0.025 0.115 0 -0 0</pose>
        <geometry>
          <cylinder>
            <length>0.05</length>
            <radius>0.002</radius>
          </cylinder>
        </geometry>
        <material>
            <script>
            <uri>file://media/materials/scripts/gazebo.material</uri>
            <name>Gazebo/Grey</name>
            </script>
        </material>
      </visual>
    </link>
    
    <joint name='head_tilt_joint' type='revolute'>
      <child>neck_link</child>
      <parent>head_tilt_link</parent>
      <axis>
        <xyz>0 1 0</xyz>
        <limit>
          <lower>-1.57</lower>
          <upper>1.57</upper>
          <effort>10</effort>
          <velocity>3</velocity>
        </limit>
        <dynamics>
          <spring_reference>0</spring_reference>
          <spring_stiffness>0</spring_stiffness>
        </dynamics>
        <use_parent_model_frame>1</use_parent_model_frame>
      </axis>
    </joint>
    
    <link name='left_shoulder_forward_link'>
      <pose frame=''>0.025 0.08 0.42 0 -0 0</pose>
      <inertial>
        <pose frame=''>0 0 0 0 -0 0</pose>
        <mass>0.5</mass>
        <inertia>
          <ixx>1</ixx>
          <ixy>0</ixy>
          <ixz>0</ixz>
          <iyy>1</iyy>
          <iyz>0</iyz>
          <izz>1</izz>
        </inertia>
      </inertial>
      <collision name='left_shoulder_forward_link_collision'>
        <pose frame=''>0 0 0 0 -0 0</pose>
        <geometry>
          <box>
            <size>0.03 0.05 0.03</size>
          </box>
        </geometry>
      </collision>
      <visual name='left_shoulder_forward_link_visual'>
        <pose frame=''>0 0 0 0 -0 0</pose>
        <geometry>
          <box>
            <size>0.03 0.05 0.03</size>
          </box>
        </geometry>
        <material>
            <script>
            <uri>file://media/materials/scripts/gazebo.material</uri>
            <name>Gazebo/Blue</name>
            </script>
        </material>
      </visual>
    </link>
    
    <joint name='left_shoulder_forward_joint' type='revolute'>
      <child>left_shoulder_forward_link</child>
      <parent>torso_link</parent>
      <axis>
        <xyz>0 0 1</xyz>
        <limit>
          <lower>-1.57</lower>
          <upper>1.57</upper>
          <effort>10</effort>
          <velocity>3</velocity>
        </limit>
        <dynamics>
          <spring_reference>0</spring_reference>
          <spring_stiffness>0</spring_stiffness>
        </dynamics>
        <use_parent_model_frame>1</use_parent_model_frame>
      </axis>
    </joint>
    
    <link name='left_shoulder_up_link'>
      <pose frame=''>0.025 0.12 0.41 0 -0.707 0</pose>
      <inertial>
        <pose frame=''>0 0 -0.025 1.57 -0 0</pose>
        <mass>1</mass>
        <inertia>
          <ixx>2.00062</ixx>
          <ixy>0</ixy>
          <ixz>0</ixz>
          <iyy>2</iyy>
          <iyz>-4.97704e-07</iyz>
          <izz>2.00062</izz>
        </inertia>
      </inertial>
      <collision name='left_shoulder_up_link_collision'>
        <pose frame=''>0 0 0 1.57 -0 0</pose>
        <geometry>
          <box>
            <size>0.03 0.05 0.03</size>
          </box>
        </geometry>
      </collision>
      <collision name='left_shoulder_up_link_fixed_joint_lump__left_upper_arm_link_collision_1'>
        <pose frame=''>0 0 -0.05 0 -0 0</pose>
        <geometry>
          <cylinder>
            <length>0.05</length>
            <radius>0.0075</radius>
          </cylinder>
        </geometry>
      </collision>
      <visual name='left_shoulder_up_link_visual'>
        <pose frame=''>0 0 0 1.57 -0 0</pose>
        <geometry>
          <box>
            <size>0.03 0.05 0.03</size>
          </box>
        </geometry>
        <material>
            <script>
            <uri>file://media/materials/scripts/gazebo.material</uri>
            <name>Gazebo/Blue</name>
            </script>
        </material>
      </visual>
      <visual name='left_shoulder_up_link_fixed_joint_lump__left_upper_arm_link_visual_1'>
        <pose frame=''>0 0 -0.05 0 -0 0</pose>
        <geometry>
          <cylinder>
            <length>0.05</length>
            <radius>0.0075</radius>
          </cylinder>
        </geometry>
        <material>
            <script>
            <uri>file://media/materials/scripts/gazebo.material</uri>
            <name>Gazebo/Grey</name>
            </script>
        </material>
      </visual>
    </link>
    
    
    <joint name='left_shoulder_up_joint' type='revolute'>
      <child>left_shoulder_up_link</child>
      <parent>left_shoulder_forward_link</parent>
      <axis>
        <xyz>0 1 0</xyz>
        <limit>
          <lower>-1.57</lower>
          <upper>1.57</upper>
          <effort>10</effort>
          <velocity>3</velocity>
        </limit>
        <dynamics>
          <spring_reference>0</spring_reference>
          <spring_stiffness>0</spring_stiffness>
        </dynamics>
        <use_parent_model_frame>1</use_parent_model_frame>
      </axis>
    </joint>
    
    
    <link name='left_elbow_link'>
      <pose frame=''>0.086154 0.12 0.330721 0 -0.707 0</pose>
      <inertial>
        <pose frame=''>0 0 -0.04 0 -0 1.57</pose>
        <mass>1</mass>
        <inertia>
          <ixx>2.0016</ixx>
          <ixy>0</ixy>
          <ixz>0</ixz>
          <iyy>2.0016</iyy>
          <iyz>0</iyz>
          <izz>2</izz>
        </inertia>
      </inertial>
      <collision name='left_elbow_link_collision'>
        <pose frame=''>0 0 0 0 -0 1.57</pose>
        <geometry>
          <box>
            <size>0.035 0.035 0.05</size>
          </box>
        </geometry>
      </collision>
      <collision name='left_elbow_link_fixed_joint_lump__left_lower_arm_link_collision_1'>
        <pose frame=''>0 0 -0.08 0 -0 0</pose>
        <geometry>
          <cylinder>
            <length>0.11</length>
            <radius>0.0075</radius>
          </cylinder>
        </geometry>
      </collision>
      <visual name='left_elbow_link_visual'>
        <pose frame=''>0 0 0 0 -0 1.57</pose>
        <geometry>
          <box>
            <size>0.035 0.035 0.05</size>
          </box>
        </geometry>
        <material>
            <script>
            <uri>file://media/materials/scripts/gazebo.material</uri>
            <name>Gazebo/Blue</name>
            </script>
        </material>
      </visual>
      <visual name='left_elbow_link_fixed_joint_lump__left_lower_arm_link_visual_1'>
        <pose frame=''>0 0 -0.08 0 -0 0</pose>
        <geometry>
          <cylinder>
            <length>0.11</length>
            <radius>0.0075</radius>
          </cylinder>
        </geometry>
        <material>
            <script>
            <uri>file://media/materials/scripts/gazebo.material</uri>
            <name>Gazebo/Grey</name>
            </script>
        </material>
      </visual>
    </link>
    
    
    <joint name='left_elbow_joint' type='revolute'>
      <child>left_elbow_link</child>
      <parent>left_shoulder_up_link</parent>
      <axis>
        <xyz>-0.649556 0 0.760314</xyz>
        <limit>
          <lower>-3.146</lower>
          <upper>3.146</upper>
          <effort>10</effort>
          <velocity>3</velocity>
        </limit>
        <dynamics>
          <spring_reference>0</spring_reference>
          <spring_stiffness>0</spring_stiffness>
        </dynamics>
        <use_parent_model_frame>1</use_parent_model_frame>
      </axis>
    </joint>
    
    
    <link name='left_wrist_link'>
      <pose frame=''>0.170596 0.12 0.23188 0 -0.707 0</pose>
      <inertial>
        <pose frame=''>0 0 -0.0275 1.57 -0 0</pose>
        <mass>1</mass>
        <inertia>
          <ixx>2.00076</ixx>
          <ixy>0</ixy>
          <ixz>0</ixz>
          <iyy>2</iyy>
          <iyz>-6.02222e-07</iyz>
          <izz>2.00076</izz>
        </inertia>
      </inertial>
      <collision name='left_wrist_link_collision'>
        <pose frame=''>0 0 0 1.57 -0 0</pose>
        <geometry>
          <box>
            <size>0.03 0.05 0.03</size>
          </box>
        </geometry>
      </collision>
      <collision name='left_wrist_link_fixed_joint_lump__left_hand_link_collision_1'>
        <pose frame=''>0 0 -0.055 0 -0 0</pose>
        <geometry>
          <box>
            <size>0.03 0.01 0.06</size>
          </box>
        </geometry>
      </collision>
      <visual name='left_wrist_link_visual'>
        <pose frame=''>0 0 0 1.57 -0 0</pose>
        <geometry>
          <box>
            <size>0.03 0.05 0.03</size>
          </box>
        </geometry>
        <material>
            <script>
            <uri>file://media/materials/scripts/gazebo.material</uri>
            <name>Gazebo/Blue</name>
            </script>
        </material>
      </visual>
      <visual name='left_wrist_link_fixed_joint_lump__left_hand_link_visual_1'>
        <pose frame=''>0 0 -0.055 0 -0 0</pose>
        <geometry>
          <box>
            <size>0.03 0.01 0.06</size>
          </box>
        </geometry>
        <material>
            <script>
            <uri>file://media/materials/scripts/gazebo.material</uri>
            <name>Gazebo/Grey</name>
            </script>
        </material>
      </visual>
    </link>
    
    
    <joint name='left_wrist_joint' type='revolute'>
      <child>left_wrist_link</child>
      <parent>left_elbow_link</parent>
      <axis>
        <xyz>0.760314 0 0.649556</xyz>
        <limit>
          <lower>-1.57</lower>
          <upper>1.57</upper>
          <effort>10</effort>
          <velocity>3</velocity>
        </limit>
        <dynamics>
          <spring_reference>0</spring_reference>
          <spring_stiffness>0</spring_stiffness>
        </dynamics>
        <use_parent_model_frame>1</use_parent_model_frame>
      </axis>
    </joint>
    
    
    <link name='right_shoulder_forward_link'>
      <pose frame=''>0.025 -0.08 0.42 0 -0 0</pose>
      <inertial>
        <pose frame=''>0 0 0 0 -0 0</pose>
        <mass>0.5</mass>
        <inertia>
          <ixx>1</ixx>
          <ixy>0</ixy>
          <ixz>0</ixz>
          <iyy>1</iyy>
          <iyz>0</iyz>
          <izz>1</izz>
        </inertia>
      </inertial>
      <collision name='right_shoulder_forward_link_collision'>
        <pose frame=''>0 0 0 0 -0 0</pose>
        <geometry>
          <box>
            <size>0.03 0.05 0.03</size>
          </box>
        </geometry>
      </collision>
      <visual name='right_shoulder_forward_link_visual'>
        <pose frame=''>0 0 0 0 -0 0</pose>
        <geometry>
          <box>
            <size>0.03 0.05 0.03</size>
          </box>
        </geometry>
        <material>
            <script>
            <uri>file://media/materials/scripts/gazebo.material</uri>
            <name>Gazebo/Blue</name>
            </script>
        </material>
      </visual>
    </link>
    
    
    <joint name='right_shoulder_forward_joint' type='revolute'>
      <child>right_shoulder_forward_link</child>
      <parent>torso_link</parent>
      <axis>
        <xyz>0 0 1</xyz>
        <limit>
          <lower>-1.57</lower>
          <upper>1.57</upper>
          <effort>10</effort>
          <velocity>3</velocity>
        </limit>
        <dynamics>
          <spring_reference>0</spring_reference>
          <spring_stiffness>0</spring_stiffness>
        </dynamics>
        <use_parent_model_frame>1</use_parent_model_frame>
      </axis>
    </joint>
    
    
    <link name='right_shoulder_up_link'>
      <pose frame=''>0.025 -0.12 0.41 0 -0.707 0</pose>
      <inertial>
        <pose frame=''>0 0 -0.025 1.57 -0 0</pose>
        <mass>1</mass>
        <inertia>
          <ixx>2.00062</ixx>
          <ixy>0</ixy>
          <ixz>0</ixz>
          <iyy>2</iyy>
          <iyz>-4.97704e-07</iyz>
          <izz>2.00062</izz>
        </inertia>
      </inertial>
      <collision name='right_shoulder_up_link_collision'>
        <pose frame=''>0 0 0 1.57 -0 0</pose>
        <geometry>
          <box>
            <size>0.03 0.05 0.03</size>
          </box>
        </geometry>
      </collision>
      <collision name='right_shoulder_up_link_fixed_joint_lump__right_upper_arm_link_collision_1'>
        <pose frame=''>0 0 -0.05 0 -0 0</pose>
        <geometry>
          <cylinder>
            <length>0.05</length>
            <radius>0.0075</radius>
          </cylinder>
        </geometry>
      </collision>
      <visual name='right_shoulder_up_link_visual'>
        <pose frame=''>0 0 0 1.57 -0 0</pose>
        <geometry>
          <box>
            <size>0.03 0.05 0.03</size>
          </box>
        </geometry>
        <material>
            <script>
            <uri>file://media/materials/scripts/gazebo.material</uri>
            <name>Gazebo/Blue</name>
            </script>
        </material>
      </visual>
      <visual name='right_shoulder_up_link_fixed_joint_lump__right_upper_arm_link_visual_1'>
        <pose frame=''>0 0 -0.05 0 -0 0</pose>
        <geometry>
          <cylinder>
            <length>0.05</length>
            <radius>0.0075</radius>
          </cylinder>
        </geometry>
        <material>
            <script>
            <uri>file://media/materials/scripts/gazebo.material</uri>
            <name>Gazebo/Grey</name>
            </script>
        </material>
      </visual>
    </link>
    
    
    <joint name='right_shoulder_up_joint' type='revolute'>
      <child>right_shoulder_up_link</child>
      <parent>right_shoulder_forward_link</parent>
      <axis>
        <xyz>0 1 0</xyz>
        <limit>
          <lower>-1.57</lower>
          <upper>1.57</upper>
          <effort>10</effort>
          <velocity>3</velocity>
        </limit>
        <dynamics>
          <spring_reference>0</spring_reference>
          <spring_stiffness>0</spring_stiffness>
        </dynamics>
        <use_parent_model_frame>1</use_parent_model_frame>
      </axis>
    </joint>
    
    
    <link name='right_elbow_link'>
      <pose frame=''>0.086154 -0.12 0.330721 0 -0.707 0</pose>
      <inertial>
        <pose frame=''>0 0 -0.04 0 -0 1.57</pose>
        <mass>1</mass>
        <inertia>
          <ixx>2.0016</ixx>
          <ixy>0</ixy>
          <ixz>0</ixz>
          <iyy>2.0016</iyy>
          <iyz>0</iyz>
          <izz>2</izz>
        </inertia>
      </inertial>
      <collision name='right_elbow_link_collision'>
        <pose frame=''>0 0 0 0 -0 1.57</pose>
        <geometry>
          <box>
            <size>0.035 0.035 0.05</size>
          </box>
        </geometry>
      </collision>
      <collision name='right_elbow_link_fixed_joint_lump__right_lower_arm_link_collision_1'>
        <pose frame=''>0 0 -0.08 0 -0 0</pose>
        <geometry>
          <cylinder>
            <length>0.11</length>
            <radius>0.0075</radius>
          </cylinder>
        </geometry>
      </collision>
      <visual name='right_elbow_link_visual'>
        <pose frame=''>0 0 0 0 -0 1.57</pose>
        <geometry>
          <box>
            <size>0.035 0.035 0.05</size>
          </box>
        </geometry>
        <material>
            <script>
            <uri>file://media/materials/scripts/gazebo.material</uri>
            <name>Gazebo/Blue</name>
            </script>
        </material>
      </visual>
      <visual name='right_elbow_link_fixed_joint_lump__right_lower_arm_link_visual_1'>
        <pose frame=''>0 0 -0.08 0 -0 0</pose>
        <geometry>
          <cylinder>
            <length>0.11</length>
            <radius>0.0075</radius>
          </cylinder>
        </geometry>
        <material>
            <script>
            <uri>file://media/materials/scripts/gazebo.material</uri>
            <name>Gazebo/Grey</name>
            </script>
        </material>
      </visual>
    </link>
    
    
    <joint name='right_elbow_joint' type='revolute'>
      <child>right_elbow_link</child>
      <parent>right_shoulder_up_link</parent>
      <axis>
        <xyz>-0.649556 0 0.760314</xyz>
        <limit>
          <lower>-3.146</lower>
          <upper>3.146</upper>
          <effort>10</effort>
          <velocity>3</velocity>
        </limit>
        <dynamics>
          <spring_reference>0</spring_reference>
          <spring_stiffness>0</spring_stiffness>
        </dynamics>
        <use_parent_model_frame>1</use_parent_model_frame>
      </axis>
    </joint>
    
    
    <link name='right_wrist_link'>
      <pose frame=''>0.170596 -0.12 0.23188 0 -0.707 0</pose>
      <inertial>
        <pose frame=''>0 0 -0.0275 1.57 -0 0</pose>
        <mass>1</mass>
        <inertia>
          <ixx>2.00076</ixx>
          <ixy>0</ixy>
          <ixz>0</ixz>
          <iyy>2</iyy>
          <iyz>-6.02222e-07</iyz>
          <izz>2.00076</izz>
        </inertia>
      </inertial>
      <collision name='right_wrist_link_collision'>
        <pose frame=''>0 0 0 1.57 -0 0</pose>
        <geometry>
          <box>
            <size>0.03 0.05 0.03</size>
          </box>
        </geometry>
      </collision>
      <collision name='right_wrist_link_fixed_joint_lump__right_hand_link_collision_1'>
        <pose frame=''>0 0 -0.055 0 -0 0</pose>
        <geometry>
          <box>
            <size>0.03 0.01 0.06</size>
          </box>
        </geometry>
      </collision>
      <visual name='right_wrist_link_visual'>
        <pose frame=''>0 0 0 1.57 -0 0</pose>
        <geometry>
          <box>
            <size>0.03 0.05 0.03</size>
          </box>
        </geometry>
        <material>
            <script>
            <uri>file://media/materials/scripts/gazebo.material</uri>
            <name>Gazebo/Blue</name>
            </script>
        </material>
      </visual>
      <visual name='right_wrist_link_fixed_joint_lump__right_hand_link_visual_1'>
        <pose frame=''>0 0 -0.055 0 -0 0</pose>
        <geometry>
          <box>
            <size>0.03 0.01 0.06</size>
          </box>
        </geometry>
        <material>
            <script>
            <uri>file://media/materials/scripts/gazebo.material</uri>
            <name>Gazebo/Grey</name>
            </script>
        </material>
      </visual>
    </link>
    
    <joint name='right_wrist_joint' type='revolute'>
      <child>right_wrist_link</child>
      <parent>right_elbow_link</parent>
      <axis>
        <xyz>0.760314 0 0.649556</xyz>
        <limit>
          <lower>-1.57</lower>
          <upper>1.57</upper>
          <effort>10</effort>
          <velocity>3</velocity>
        </limit>
        <dynamics>
          <spring_reference>0</spring_reference>
          <spring_stiffness>0</spring_stiffness>
        </dynamics>
        <use_parent_model_frame>1</use_parent_model_frame>
      </axis>
    </joint>
    
  </model>
</sdf>
